Workbook

Sheet 3-Statement Model
A4: x | C4: Income Statement | E4: 2020 | F4: =E4+1 -> 2021 | G4: =F4+1 -> 2022 | H4: =G4+1 -> 2023 | I4: =H4+1 -> 2024 | J4: =I4+1 -> 2025 | K4: =J4+1 -> 2026 | L4: =K4+1 -> 2027 | M4: =L4+1 -> 2028 | ... S4: =R4+1 -> 2034
B6: x | C6: Revenue | E6: 2020 | F6: =E6+1 -> 2021 | G6: =F6+1 -> 2022 | H6: =G6+1 -> 2023 | I6: =H6+1 -> 2024 | J6: =I6+1 -> 2025 | K6: =J6+1 -> 2026 | L6: =K6+1 -> 2027 | M6: =L6+1 -> 2028 | ... S6: =R6+1 -> 2034
C8: EMEA | E8: 3495.4 | F8: 4071.4 | G8: 4143.5 | H8: 4879.7 | I8: 5095.2 | J8: =I8*(1+J9) -> 5033.8156 | K8: =J8*(1+K9) -> 5298.0229 | L8: =K8*(1+L9) -> 5596.4305 | M8: =L8*(1+M9) -> 5899.5453 | N8: =M8*(1+N9) -> 6215.1595 | O8: =N8*(1+O9) -> 6515.9637 | P8: =O8*(1+P9) -> 6798.0973 | Q8: =P8*(1+Q9) -> 7057.7794 | ... S8: =R8*(1+S9) -> 7495.5481
C9: % growth | E9: =IF(ISNUMBER(B8),(E8-B8)/B8, "--") -> -- | F9: =IF(ISNUMBER(E8),(F8-E8)/E8, "--") -> 0.16478801 | G9: =IF(ISNUMBER(F8),(G8-F8)/F8, "--") -> 0.017708896 | H9: =IF(ISNUMBER(G8),(H8-G8)/G8, "--") -> 0.17767588 | I9: =IF(ISNUMBER(H8),(I8-H8)/H8, "--") -> 0.044162551 | J9: =Assumptions!J10 -> -0.01204749 | K9: =Assumptions!K10 -> 0.052486486 | L9: =Assumptions!L10 -> 0.056324324 | M9: =Assumptions!M10 -> 0.054162162 | N9: =Assumptions!N10 -> 0.053498069 | O9: =Assumptions!O10 -> 0.048398456 | P9: =Assumptions!P10 -> 0.043298842 | Q9: =Assumptions!Q10 -> 0.038199228 | ... S9: =Assumptions!S10 -> 0.028
C10: % of revenue | E10: =E8/E24 -> 0.44371382 | F10: =F8/F24 -> 0.44004194 | G10: =G8/G24 -> 0.39492747 | H10: =H8/H24 -> 0.43419109 | I10: =I8/I24 -> 0.43315113 | J10: =J8/J24 -> 0.44487169 | K10: =K8/K24 -> 0.44478295 | L10: =L8/L24 -> 0.44044314 | ... S10: =S8/S24 -> 0.43548745
C12: Americas | E12: 2012.2 | F12: 2427.4 | G12: 3193.5 | H12: 3735.9 | I12: 4096.9 | J12: =I12*(1+J13) -> 3928.9271 | K12: =J12*(1+K13) -> 4105.7288 | L12: =K12*(1+L13) -> 4434.1871 | M12: =L12*(1+M13) -> 4753.4486 | N12: =M12*(1+N13) -> 5033.9021 | O12: =N12*(1+O13) -> 5300.3968 | P12: =O12*(1+P13) -> 5548.8794 | Q12: =P12*(1+Q13) -> 5775.3847 | ... S12: =R12*(1+S13) -> 6147.6522
C13: % growth | E13: =IF(ISNUMBER(B12),(E12-B12)/B12, "--") -> -- | F13: =IF(ISNUMBER(E12),(F12-E12)/E12, "--") -> 0.20634132 | G13: =IF(ISNUMBER(F12),(G12-F12)/F12, "--") -> 0.31560517 | H13: =IF(ISNUMBER(G12),(H12-G12)/G12, "--") -> 0.169845 | I13: =IF(ISNUMBER(H12),(I12-H12)/H12, "--") -> 0.096629995 | J13: =Assumptions!J11 -> -0.041 | K13: =Assumptions!K11 -> 0.045 | L13: =Assumptions!L11 -> 0.08 | M13: =Assumptions!M11 -> 0.072 | N13: =Assumptions!N11 -> 0.059 | O13: =Assumptions!O11 -> 0.05294 | P13: =Assumptions!P11 -> 0.04688 | Q13: =Assumptions!Q11 -> 0.04082 | ... S13: =Assumptions!S11 -> 0.0287
C14: % of revenue | E14: =E12/E24 -> 0.25543313 | F14: =F12/F24 -> 0.26235639 | G14: =G12/G24 -> 0.30438056 | H14: =H12/H24 -> 0.33241685 | I14: =I12/I24 -> 0.34828404 | J14: =J12/J24 -> 0.34722536 | K14: =K12/K24 -> 0.34468672 | L14: =L12/L24 -> 0.34897375 | ... S14: =S12/S24 -> 0.3571754
C16: Asia/Pacific | E16: 1723.3 | F16: 2080.9 | G16: 2350.6 | H16: 2623 | I16: 2571 | J16: =I16*(1+J17) -> 2352.465 | K16: =J16*(1+K17) -> 2507.7277 | L16: =K16*(1+L17) -> 2675.7454 | M16: =L16*(1+M17) -> 2828.2629 | N16: =M16*(1+N17) -> 2975.3326 | O16: =N16*(1+O17) -> 3115.2327 | P16: =O16*(1+P17) -> 3246.1971 | Q16: =P16*(1+Q17) -> 3366.5012 | ... S16: =R16*(1+S17) -> 3568.6575
C17: % growth | E17: =IF(ISNUMBER(B16),(E16-B16)/B16, "--") -> -- | F17: =IF(ISNUMBER(E16),(F16-E16)/E16, "--") -> 0.20750885 | G17: =IF(ISNUMBER(F16),(G16-F16)/F16, "--") -> 0.12960738 | H17: =IF(ISNUMBER(G16),(H16-G16)/G16, "--") -> 0.11588531 | I17: =IF(ISNUMBER(H16),(I16-H16)/H16, "--") -> -0.019824628 | J17: =Assumptions!J12 -> -0.085 | K17: =Assumptions!K12 -> 0.066 | L17: =Assumptions!L12 -> 0.067 | M17: =Assumptions!M12 -> 0.057 | N17: =Assumptions!N12 -> 0.052 | O17: =Assumptions!O12 -> 0.04702 | P17: =Assumptions!P12 -> 0.04204 | Q17: =Assumptions!Q12 -> 0.03706 | ... S17: =Assumptions!S12 -> 0.0271
C18: % of revenue | E18: =E16/E24 -> 0.21875952 | F18: =F16/F24 -> 0.22490624 | G18: =G16/G24 -> 0.22404163 | H18: =H16/H24 -> 0.23339206 | I18: =I16/I24 -> 0.21856483 | J18: =J16/J24 -> 0.20790294 | K18: =K16/K24 -> 0.21053033 | L18: =L16/L24 -> 0.21058311 | ... S18: =S16/S24 -> 0.20733715
C20: Global Business | E20: 646.7 | F20: 672.6 | G20: 804.2 | H20: 0 | I20: 0 | J20: =I20*(1+J21) -> 0 | K20: =J20*(1+K21) -> 0 | L20: =K20*(1+L21) -> 0 | M20: =L20*(1+M21) -> 0 | N20: =M20*(1+N21) -> 0 | O20: =N20*(1+O21) -> 0 | P20: =O20*(1+P21) -> 0 | Q20: =P20*(1+Q21) -> 0 | ... S20: =R20*(1+S21) -> 0
C21: % growth | E21: =IF(ISNUMBER(B20),(E20-B20)/B20, "--") -> -- | F21: =IF(ISNUMBER(E20),(F20-E20)/E20, "--") -> 0.040049482 | G21: =IF(ISNUMBER(F20),(G20-F20)/F20, "--") -> 0.19565864 | H21: =IF(ISNUMBER(G20),(H20-G20)/G20, "--") -> -1 | I21: =IF(ISNUMBER(H20), IF(H20=0, "--", (I20-H20)/H20), "--") -> -- | J21: =Assumptions!J13 -> 0 | K21: =Assumptions!K13 -> 0 | L21: =Assumptions!L13 -> 0 | M21: =Assumptions!M13 -> 0 | N21: =Assumptions!N13 -> 0 | O21: =Assumptions!O13 -> 0 | P21: =Assumptions!P13 -> 0 | Q21: =Assumptions!Q13 -> 0 | ... S21: =Assumptions!S13 -> 0
C22: % of revenue | E22: =E20/E24 -> 0.082093531 | F22: =F20/F24 -> 0.072695438 | G22: =G20/G24 -> 0.076650336 | H22: =H20/H24 -> 0 | I22: =I20/I24 -> 0 | J22: =J20/J24 -> 0 | K22: =K20/K24 -> 0 | L22: =L20/L24 -> 0 | ... S22: =S20/S24 -> 0
C24: Revenue | E24: =E8+E12+E16+E20 -> 7877.6 | F24: =F8+F12+F16+F20 -> 9252.3 | G24: =G8+G12+G16+G20 -> 10491.8 | H24: =H8+H12+H16+H20 -> 11238.6 | I24: =I8+I12+I16+I20 -> 11763.1 | J24: =J8+J12+J16+J20 -> 11315.208 | K24: =K8+K12+K16+K20 -> 11911.479 | L24: =L8+L12+L16+L20 -> 12706.363 | ... S24: =S8+S12+S16+S20 -> 17211.858
C25: % growth | E25: =IF(ISNUMBER(B24),(E24-B24)/B24, "--") -> -- | F25: =IF(ISNUMBER(E24),(F24-E24)/E24, "--") -> 0.17450746 | G25: =IF(ISNUMBER(F24),(G24-F24)/F24, "--") -> 0.13396669 | H25: =IF(ISNUMBER(G24),(H24-G24)/G24, "--") -> 0.071179397 | I25: =IF(ISNUMBER(H24),(I24-H24)/H24, "--") -> 0.046669514 | J25: =IF(ISNUMBER(I24),(J24-I24)/I24, "--") -> -0.038076041 | K25: =IF(ISNUMBER(J24),(K24-J24)/J24, "--") -> 0.052696488 | L25: =IF(ISNUMBER(K24),(L24-K24)/K24, "--") -> 0.066732569 | M25: =IF(ISNUMBER(L24),(M24-L24)/L24, "--") -> 0.0609847 | ... S25: =IF(ISNUMBER(R24),(S24-R24)/R24, "--") -> 0.02806309
B27: x | C27: COGS | E27: 2020 | F27: =E27+1 -> 2021 | G27: =F27+1 -> 2022 | H27: =G27+1 -> 2023 | I27: =H27+1 -> 2024 | J27: =I27+1 -> 2025 | K27: =J27+1 -> 2026 | L27: =K27+1 -> 2027 | M27: =L27+1 -> 2028 | ... S27: =R27+1 -> 2034
C29: Cost of Goods Sold | E29: 3562.7 | F29: 4461 | G29: 5312 | H29: 5213.8 | I29: 5347.1 | J29: =J30*J24 -> 5091.8435 | K29: =K30*K24 -> 5360.1657 | L29: =L30*L24 -> 5717.8634 | M29: =M30*M24 -> 6066.5656 | N29: =N30*N24 -> 6400.9774 | O29: =O30*O24 -> 6719.217 | P29: =P30*P24 -> 7016.9283 | Q29: =Q30*Q24 -> 7289.8494 | ... S29: =S30*S24 -> 7745.336
C30: % of revenue | E30: =E29/E24 -> 0.45225703 | F30: =F29/F24 -> 0.48215038 | G30: =G29/G24 -> 0.50630016 | H30: =H29/H24 -> 0.46391899 | I30: =I29/I24 -> 0.45456555 | J30: =Assumptions!J16 -> 0.45 | K30: =Assumptions!K16 -> 0.45 | L30: =Assumptions!L16 -> 0.45 | M30: =Assumptions!M16 -> 0.45 | N30: =Assumptions!N16 -> 0.45 | O30: =Assumptions!O16 -> 0.45 | P30: =Assumptions!P16 -> 0.45 | Q30: =Assumptions!Q16 -> 0.45 | ... S30: =Assumptions!S16 -> 0.45
C32: Gross Profit | E32: =E24-E29 -> 4314.9 | F32: =F24-F29 -> 4791.3 | G32: =G24-G29 -> 5179.8 | H32: =H24-H29 -> 6024.8 | I32: =I24-I29 -> 6416 | J32: =J24-J29 -> 6223.3642 | K32: =K24-K29 -> 6551.3137 | L32: =L24-L29 -> 6988.4997 | ... S32: =S24-S29 -> 9466.5218
C33: Gross margin % | E33: =E32/E24 -> 0.54774297 | F33: =F32/F24 -> 0.51784962 | G33: =G32/G24 -> 0.49369984 | H33: =H32/H24 -> 0.53608101 | I33: =I32/I24 -> 0.54543445 | J33: =J32/J24 -> 0.55 | K33: =K32/K24 -> 0.55 | L33: =L32/L24 -> 0.55 | ... S33: =S32/S24 -> 0.55
B35: x | C35: OpEx | E35: 2020 | F35: =E35+1 -> 2021 | G35: =F35+1 -> 2022 | H35: =G35+1 -> 2023 | I35: =H35+1 -> 2024 | J35: =I35+1 -> 2025 | K35: =J35+1 -> 2026 | L35: =K35+1 -> 2027 | M35: =L35+1 -> 2028 | ... S35: =R35+1 -> 2034
C37: Personnel Expenses | E37: 1525.9 | F37: 1635.3 | G37: 1710.5 | H37: 2006.8 | I37: 2143.6 | J37: =J38*J24 -> 2138.5743 | K37: =K38*K24 -> 2167.8893 | L37: =L38*L24 -> 2249.0263 | M37: =M38*M24 -> 2386.1825 | N37: =N38*N24 -> 2517.7178 | O37: =O38*O24 -> 2642.892 | P37: =P38*P24 -> 2759.9918 | Q37: =Q38*Q24 -> 2867.3408 | ... S37: =S38*S24 -> 3046.4988
C38: % of revenue | E38: =E37/E24 -> 0.19370113 | F38: =F37/F24 -> 0.17674524 | G38: =G37/G24 -> 0.16303208 | H38: =H37/H24 -> 0.17856317 | I38: =I37/I24 -> 0.18223087 | J38: =Assumptions!J19 -> 0.189 | K38: =Assumptions!K19 -> 0.182 | L38: =Assumptions!L19 -> 0.177 | M38: =Assumptions!M19 -> 0.177 | N38: =Assumptions!N19 -> 0.177 | O38: =Assumptions!O19 -> 0.177 | P38: =Assumptions!P19 -> 0.177 | Q38: =Assumptions!Q19 -> 0.177 | ... S38: =Assumptions!S19 -> 0.177
C40: Production and Operations | E40: 399.5 | F40: 466.5 | G40: 498.5 | H40: 573.5 | I40: 621.6 | J40: =J41*J24 -> 588.3908 | K40: =K41*K24 -> 607.48545 | L40: =L41*L24 -> 635.31815 | M40: =M41*M24 -> 660.58158 | N40: =N41*N24 -> 696.99532 | O40: =O41*O24 -> 731.64807 | P40: =P41*P24 -> 764.06552 | Q40: =Q41*Q24 -> 793.7836 | ... S40: =S41*S24 -> 843.38103
C41: % of revenue | E41: =E40/E24 -> 0.050713415 | F41: =F40/F24 -> 0.050419896 | G41: =G40/G24 -> 0.047513296 | H41: =H40/H24 -> 0.051029488 | I41: =I40/I24 -> 0.052843213 | J41: =Assumptions!J20 -> 0.052 | K41: =Assumptions!K20 -> 0.051 | L41: =Assumptions!L20 -> 0.05 | M41: =Assumptions!M20 -> 0.049 | N41: =Assumptions!N20 -> 0.049 | O41: =Assumptions!O20 -> 0.049 | P41: =Assumptions!P20 -> 0.049 | Q41: =Assumptions!Q20 -> 0.049 | ... S41: =Assumptions!S20 -> 0.049
C43: Logistics and Distribution | E43: 401.6 | F43: 477 | G43: 519.4 | H43: 566.1 | I43: 605.3 | J43: =J44*J24 -> 565.76039 | K43: =K44*K24 -> 583.66249 | L43: =L44*L24 -> 622.61179 | M43: =M44*M24 -> 647.10033 | N43: =N44*N24 -> 682.77092 | O43: =O44*O24 -> 716.71648 | P43: =P44*P24 -> 748.47235 | Q43: =Q44*Q24 -> 777.58394 | ... S43: =S44*S24 -> 826.16917
C44: % of revenue | E44: =E43/E24 -> 0.050979994 | F44: =F43/F24 -> 0.051554749 | G44: =G43/G24 -> 0.049505328 | H44: =H43/H24 -> 0.050371043 | I44: =I43/I24 -> 0.051457524 | J44: =Assumptions!J21 -> 0.05 | K44: =Assumptions!K21 -> 0.049 | L44: =Assumptions!L21 -> 0.049 | M44: =Assumptions!M21 -> 0.048 | N44: =Assumptions!N21 -> 0.048 | O44: =Assumptions!O21 -> 0.048 | P44: =Assumptions!P21 -> 0.048 | Q44: =Assumptions!Q21 -> 0.048 | ... S44: =Assumptions!S21 -> 0.048
C46: Sales, Marketing and Travel Costs | E46: 212 | F46: 235.1 | G46: 303.5 | H46: 370.5 | I46: 370.9 | J46: =J47*J24 -> 350.77144 | K46: =K47*K24 -> 357.34438 | L46: =L47*L24 -> 368.48453 | M46: =M47*M24 -> 390.95645 | N46: =N47*N24 -> 412.50743 | O46: =O47*O24 -> 433.0162 | P46: =P47*P24 -> 452.20204 | Q46: =Q47*Q24 -> 469.79029 | ... S46: =S47*S24 -> 499.14388
C47: % of revenue | E47: =E46/E24 -> 0.02691175 | F47: =F46/F24 -> 0.025409898 | G47: =G46/G24 -> 0.028927353 | H47: =H46/H24 -> 0.03296674 | I47: =I46/I24 -> 0.031530804 | J47: =Assumptions!J22 -> 0.031 | K47: =Assumptions!K22 -> 0.03 | L47: =Assumptions!L22 -> 0.029 | M47: =Assumptions!M22 -> 0.029 | N47: =Assumptions!N22 -> 0.029 | O47: =Assumptions!O22 -> 0.029 | P47: =Assumptions!P22 -> 0.029 | Q47: =Assumptions!Q22 -> 0.029 | ... S47: =Assumptions!S22 -> 0.029
C49: Administration Costs | E49: 278.2 | F49: 239.4 | G49: 183.7 | H49: 463.2 | I49: 405.1 | J49: =J50*J24 -> 407.34748 | K49: =K50*K24 -> 416.90178 | L49: =L50*L24 -> 444.72271 | M49: =M50*M24 -> 458.36273 | N49: =N50*N24 -> 483.6294 | O49: =O50*O24 -> 507.67417 | P49: =P50*P24 -> 530.16791 | Q49: =Q50*Q24 -> 550.78862 | ... S49: =S50*S24 -> 585.20316
C50: % of revenue | E50: =E49/E24 -> 0.035315324 | F50: =F49/F24 -> 0.025874647 | G50: =G49/G24 -> 0.017508912 | H50: =H49/H24 -> 0.041215098 | I50: =I49/I24 -> 0.034438201 | J50: =Assumptions!J23 -> 0.036 | K50: =Assumptions!K23 -> 0.035 | L50: =Assumptions!L23 -> 0.035 | M50: =Assumptions!M23 -> 0.034 | N50: =Assumptions!N23 -> 0.034 | O50: =Assumptions!O23 -> 0.034 | P50: =Assumptions!P23 -> 0.034 | Q50: =Assumptions!Q23 -> 0.034 | ... S50: =Assumptions!S23 -> 0.034
C52: Operating Expenses | E52: =E37+E40+E43+E46+E49 -> 2817.2 | F52: =F37+F40+F43+F46+F49 -> 3053.3 | G52: =G37+G40+G43+G46+G49 -> 3215.6 | H52: =H37+H40+H43+H46+H49 -> 3980.1 | I52: =I37+I40+I43+I46+I49 -> 4146.5 | J52: =J37+J40+J43+J46+J49 -> 4050.8444 | K52: =K37+K40+K43+K46+K49 -> 4133.2834 | L52: =L37+L40+L43+L46+L49 -> 4320.1634 | ... S52: =S37+S40+S43+S46+S49 -> 5800.3961
C53: % of revenue | E53: =E52/E24 -> 0.35762161 | F53: =F52/F24 -> 0.33000443 | G53: =G52/G24 -> 0.30648697 | H53: =H52/H24 -> 0.35414553 | I53: =I52/I24 -> 0.35250062 | J53: =J52/J24 -> 0.358 | K53: =K52/K24 -> 0.347 | L53: =L52/L24 -> 0.34 | ... S53: =S52/S24 -> 0.337
C55: EBITDA | E55: =E32-E52 -> 1497.7 | F55: =F32-F52 -> 1738 | G55: =G32-G52 -> 1964.2 | H55: =H32-H52 -> 2044.7 | I55: =I32-I52 -> 2269.5 | J55: =J32-J52 -> 2172.5199 | K55: =K32-K52 -> 2418.0303 | L55: =L32-L52 -> 2668.3362 | ... S55: =S32-S52 -> 3666.1257
C56: % of revenue | E56: =E55/E24 -> 0.19012136 | F56: =F55/F24 -> 0.18784518 | G56: =G55/G24 -> 0.18721287 | H56: =H55/H24 -> 0.18193547 | I56: =I55/I24 -> 0.19293384 | J56: =J55/J24 -> 0.192 | K56: =K55/K24 -> 0.203 | L56: =L55/L24 -> 0.21 | ... S56: =S55/S24 -> 0.213
B58: x | C58: Depreciation and Amortization | E58: 2020 | F58: =E58+1 -> 2021 | G58: =F58+1 -> 2022 | H58: =G58+1 -> 2023 | I58: =H58+1 -> 2024 | J58: =I58+1 -> 2025 | K58: =J58+1 -> 2026 | L58: =K58+1 -> 2027 | M58: =L58+1 -> 2028 | ... S58: =R58+1 -> 2034
C60: Depreciation | E60: =169.3+85.5 -> 254.8 | F60: =165.8+84.5 -> 250.3 | G60: =174.5+86.1 -> 260.6 | H60: =200+106 -> 306 | I60: =220.7+120.8 -> 341.5 | J60: =J300 -> 383.24313 | K60: =K300 -> 423.62303 | L60: =L300 -> 465.19318 | M60: =M300 -> 474.04774 | N60: =N300 -> 438.18835 | O60: =O300 -> 481.25332 | P60: =P300 -> 502.07297 | Q60: =Q300 -> 521.07452 | ... S60: =S300 -> 320.73894
C61: % of revenue | E61: =E60/E24 -> 0.032344877 | F61: =F60/F24 -> 0.027052733 | G61: =G60/G24 -> 0.024838445 | H61: =H60/H24 -> 0.027227591 | I61: =I60/I24 -> 0.029031463 | J61: =J60/J24 -> 0.033869739 | K61: =K60/K24 -> 0.035564267 | L61: =L60/L24 -> 0.036611041 | ... S61: =S60/S24 -> 0.018634766
C63: Amortization | E63: 112.3 | F63: 116.3 | G63: 123.9 | H63: 179.3 | I63: 214.1 | J63: =J303 -> 215.29748 | K63: =K303 -> 217.062 | L63: =L303 -> 218.94426 | M63: =M303 -> 220.94131 | N63: =N303 -> 223.04844 | O63: =O303 -> 225.26034 | P63: =P303 -> 227.57024 | Q63: =Q303 -> 229.96999 | ... S63: =S303 -> 145.48674
...

Sheet DCF
B2: Free Cash Flow to Firm | E2: 2025 | F2: =E2+1 -> 2026 | G2: =F2+1 -> 2027 | H2: =G2+1 -> 2028 | I2: =H2+1 -> 2029 | J2: =I2+1 -> 2030 | K2: =J2+1 -> 2031 | L2: =K2+1 -> 2032 | M2: =L2+1 -> 2033 | N2: =M2+1 -> 2034
B4: Revenue | E4: ='3-Statement Model'!J24 -> 11315.208 | F4: ='3-Statement Model'!K24 -> 11911.479 | G4: ='3-Statement Model'!L24 -> 12706.363 | H4: ='3-Statement Model'!M24 -> 13481.257 | I4: ='3-Statement Model'!N24 -> 14224.394 | J4: ='3-Statement Model'!O24 -> 14931.593 | K4: ='3-Statement Model'!P24 -> 15593.174 | L4: ='3-Statement Model'!Q24 -> 16199.665 | ... N4: ='3-Statement Model'!S24 -> 17211.858
B5: % growth | E5: ='3-Statement Model'!J25 -> -0.038076041 | F5: ='3-Statement Model'!K25 -> 0.052696488 | G5: ='3-Statement Model'!L25 -> 0.066732569 | H5: ='3-Statement Model'!M25 -> 0.0609847 | I5: ='3-Statement Model'!N25 -> 0.055123749 | J5: ='3-Statement Model'!O25 -> 0.04971734 | K5: ='3-Statement Model'!P25 -> 0.04430744 | L5: ='3-Statement Model'!Q25 -> 0.038894673 | ... N5: ='3-Statement Model'!S25 -> 0.02806309
B7: EBITDA | E7: ='3-Statement Model'!J55 -> 2172.5199 | F7: ='3-Statement Model'!K55 -> 2418.0303 | G7: ='3-Statement Model'!L55 -> 2668.3362 | H7: ='3-Statement Model'!M55 -> 2871.5077 | I7: =I8*I4 -> 3029.796 | J7: =J8*J4 -> 3180.4294 | K7: =K8*K4 -> 3321.346 | L7: =L8*L4 -> 3450.5287 | M7: =M8*M4 -> 3566.0513 | N7: =N8*N4 -> 3666.1257
B8: % of revenue | E8: =E7/E4 -> 0.192 | F8: =F7/F4 -> 0.203 | G8: =G7/G4 -> 0.21 | H8: =H7/H4 -> 0.213 | I8: 0.213 | J8: =I8 -> 0.213 | K8: =J8 -> 0.213 | L8: =K8 -> 0.213 | M8: =L8 -> 0.213 | N8: =M8 -> 0.213
B10: D&A | E10: ='3-Statement Model'!J66 -> 598.54062 | F10: ='3-Statement Model'!K66 -> 640.68503 | G10: ='3-Statement Model'!L66 -> 684.13744 | H10: ='3-Statement Model'!M66 -> 694.98905 | I10: ='3-Statement Model'!N66 -> 661.2368 | J10: ='3-Statement Model'!O66 -> 706.51366 | K10: ='3-Statement Model'!P66 -> 729.64321 | L10: ='3-Statement Model'!Q66 -> 751.0445 | ... N10: ='3-Statement Model'!S66 -> 466.22568
B12: EBIT | E12: =E7-E10 -> 1573.9793 | F12: =F7-F10 -> 1777.3453 | G12: =G7-G10 -> 1984.1988 | H12: =H7-H10 -> 2176.5187 | I12: =I7-I10 -> 2368.5592 | J12: =J7-J10 -> 2473.9157 | K12: =K7-K10 -> 2591.7028 | L12: =L7-L10 -> 2699.4842 | ... N12: =N7-N10 -> 3199.9
B14: EBIT | E14: ='3-Statement Model'!J72 -> 1573.9793 | F14: ='3-Statement Model'!K72 -> 1777.3453 | G14: ='3-Statement Model'!L72 -> 1984.1988 | H14: ='3-Statement Model'!M72 -> 2176.5187 | I14: ='3-Statement Model'!N72 -> 2368.5592 | J14: ='3-Statement Model'!O72 -> 2473.9157 | K14: ='3-Statement Model'!P72 -> 2591.7028 | L14: ='3-Statement Model'!Q72 -> 2699.4842 | ... N14: ='3-Statement Model'!S72 -> 3199.9
B15: % of revenue | E15: ='3-Statement Model'!J73 -> 0.13910299 | F15: ='3-Statement Model'!K73 -> 0.14921281 | G15: ='3-Statement Model'!L73 -> 0.15615789 | H15: ='3-Statement Model'!M73 -> 0.16144776 | I15: ='3-Statement Model'!N73 -> 0.16651389 | J15: ='3-Statement Model'!O73 -> 0.1656833 | K15: ='3-Statement Model'!P73 -> 0.16620752 | L15: ='3-Statement Model'!Q73 -> 0.16663827 | ... N15: ='3-Statement Model'!S73 -> 0.18591253
B17: Taxes | E17: =E12*E18 -> 317.61552 | F17: =F12*F18 -> 358.65304 | G17: =G12*G18 -> 400.39431 | H17: =H12*H18 -> 439.2028 | I17: =I12*I18 -> 477.95493 | J17: =J12*J18 -> 499.21498 | K17: =K12*K18 -> 522.98341 | L17: =L12*L18 -> 544.73277 | ... N17: =N12*N18 -> 645.71239
B18: % tax rate | E18: =Assumptions!J50 -> 0.20179143 | F18: =Assumptions!K50 -> 0.20179143 | G18: =Assumptions!L50 -> 0.20179143 | H18: =Assumptions!M50 -> 0.20179143 | I18: =Assumptions!N50 -> 0.20179143 | J18: =Assumptions!O50 -> 0.20179143 | K18: =Assumptions!P50 -> 0.20179143 | L18: =Assumptions!Q50 -> 0.20179143 | ... N18: =Assumptions!S50 -> 0.20179143
B20: NOPAT | E20: =E12-E17 -> 1256.3637 | F20: =F12-F17 -> 1418.6923 | G20: =G12-G17 -> 1583.8045 | H20: =H12-H17 -> 1737.3158 | I20: =I12-I17 -> 1890.6042 | J20: =J12-J17 -> 1974.7007 | K20: =K12-K17 -> 2068.7194 | L20: =L12-L17 -> 2154.7514 | ... N20: =N12-N17 -> 2554.1876
B21: % of revenue | E21: =E20/E4 -> 0.1110332 | F21: =F20/F4 -> 0.11910294 | G21: =G20/G4 -> 0.12464656 | H21: =H20/H4 -> 0.12886898 | I21: =I20/I4 -> 0.13291281 | J21: =J20/J4 -> 0.13224983 | K21: =K20/K4 -> 0.13266827 | L21: =L20/L4 -> 0.1330121 | ... N21: =N20/N4 -> 0.14839698
B23: D&A | E23: ='3-Statement Model'!J158 -> 598.54062 | F23: ='3-Statement Model'!K158 -> 640.68503 | G23: ='3-Statement Model'!L158 -> 684.13744 | H23: ='3-Statement Model'!M158 -> 694.98905 | I23: ='3-Statement Model'!N158 -> 661.2368 | J23: ='3-Statement Model'!O158 -> 706.51366 | K23: ='3-Statement Model'!P158 -> 729.64321 | L23: ='3-Statement Model'!Q158 -> 751.0445 | ... N23: ='3-Statement Model'!S158 -> 466.22568
B24: Provisions | E24: ='3-Statement Model'!J159 -> -0.62103703 | F24: ='3-Statement Model'!K159 -> 2.2911886 | G24: ='3-Statement Model'!L159 -> 3.0543598 | H24: ='3-Statement Model'!M159 -> 2.9775482 | I24: ='3-Statement Model'!N159 -> 2.8555238 | J24: ='3-Statement Model'!O159 -> 2.7174296 | K24: ='3-Statement Model'!P159 -> 2.5421399 | L24: ='3-Statement Model'!Q159 -> 2.330458 | ... N24: ='3-Statement Model'!S159 -> 1.8053446
B25: Accounts receivable | E25: ='3-Statement Model'!J161 -> 35.960731 | F25: ='3-Statement Model'!K161 -> -47.451476 | G25: ='3-Statement Model'!L161 -> -73.371208 | H25: ='3-Statement Model'!M161 -> -137.817 | I25: ='3-Statement Model'!N161 -> -132.16905 | J25: ='3-Statement Model'!O161 -> -125.77731 | K25: ='3-Statement Model'!P161 -> -117.66396 | L25: ='3-Statement Model'!Q161 -> -107.86618 | ... N25: ='3-Statement Model'!S161 -> -83.561093
B26: Inventories | E26: ='3-Statement Model'!J162 -> -46.12561 | F26: ='3-Statement Model'!K162 -> -0.086021971 | G26: ='3-Statement Model'!L162 -> 10.531299 | H26: ='3-Statement Model'!M162 -> -84.438216 | I26: ='3-Statement Model'!N162 -> -80.97781 | J26: ='3-Statement Model'!O162 -> -77.061695 | K26: ='3-Statement Model'!P162 -> -72.090777 | L26: ='3-Statement Model'!Q162 -> -66.087837 | ... N26: ='3-Statement Model'!S162 -> -51.196511
B27: Prepaid expense and accrued income | E27: ='3-Statement Model'!J163 -> 24.698368 | F27: ='3-Statement Model'!K163 -> -13.110972 | G27: ='3-Statement Model'!L163 -> -17.478101 | H27: ='3-Statement Model'!M163 -> -17.038558 | I27: ='3-Statement Model'!N163 -> -16.340292 | J27: ='3-Statement Model'!O163 -> -15.55007 | K27: ='3-Statement Model'!P163 -> -14.547002 | L27: ='3-Statement Model'!Q163 -> -13.335685 | ... N27: ='3-Statement Model'!S163 -> -10.330805
B28: Other current assets | E28: ='3-Statement Model'!J164 -> 0 | F28: ='3-Statement Model'!K164 -> 0 | G28: ='3-Statement Model'!L164 -> 0 | H28: ='3-Statement Model'!M164 -> 0 | I28: ='3-Statement Model'!N164 -> 0 | J28: ='3-Statement Model'!O164 -> 0 | K28: ='3-Statement Model'!P164 -> 0 | L28: ='3-Statement Model'!Q164 -> 0 | ... N28: ='3-Statement Model'!S164 -> 0
B29: Accounts payable | E29: ='3-Statement Model'!J165 -> -96.279512 | F29: ='3-Statement Model'!K165 -> 47.064606 | G29: ='3-Statement Model'!L165 -> 77.615656 | H29: ='3-Statement Model'!M165 -> 75.663763 | I29: ='3-Statement Model'!N165 -> 72.562948 | J29: ='3-Statement Model'!O165 -> 69.053778 | K29: ='3-Statement Model'!P165 -> 64.599416 | L29: ='3-Statement Model'!Q165 -> 59.220276 | ... N29: ='3-Statement Model'!S165 -> 45.876391
B30: Accrued expenses and deferred income | E30: ='3-Statement Model'!J166 -> 2.3605938 | F30: ='3-Statement Model'!K166 -> 33.001734 | G30: ='3-Statement Model'!L166 -> 43.994269 | H30: ='3-Statement Model'!M166 -> 42.887893 | I30: ='3-Statement Model'!N166 -> 41.130282 | J30: ='3-Statement Model'!O166 -> 39.141207 | K30: ='3-Statement Model'!P166 -> 36.616376 | L30: ='3-Statement Model'!Q166 -> 33.567361 | ... N30: ='3-Statement Model'!S166 -> 26.003752
B31: Income tax liabilities | E31: ='3-Statement Model'!J167 -> 0 | F31: ='3-Statement Model'!K167 -> 0 | G31: ='3-Statement Model'!L167 -> 0 | H31: ='3-Statement Model'!M167 -> 0 | I31: ='3-Statement Model'!N167 -> 0 | J31: ='3-Statement Model'!O167 -> 0 | K31: ='3-Statement Model'!P167 -> 0 | L31: ='3-Statement Model'!Q167 -> 0 | ... N31: ='3-Statement Model'!S167 -> 0
B33: CapEx property, plant and equipment | E33: ='3-Statement Model'!J172 -> -498.20841 | F33: ='3-Statement Model'!K172 -> -522.68374 | G33: ='3-Statement Model'!L172 -> -555.31155 | H33: ='3-Statement Model'!M172 -> -587.11882 | I33: ='3-Statement Model'!N172 -> -576.64832 | J33: ='3-Statement Model'!O172 -> -597.7343 | K33: ='3-Statement Model'!P172 -> -565.62112 | L33: ='3-Statement Model'!Q172 -> -526.74439 | ... N33: ='3-Statement Model'!S172 -> -430.29644
B34: % of revenue | E34: =-E33/E4 -> 0.044029984 | F34: =-F33/F4 -> 0.043880674 | G34: =-G33/G4 -> 0.043703422 | H34: =-H33/H4 -> 0.043550748 | I34: =-I33/I4 -> 0.040539394 | J34: =-J33/J4 -> 0.040031515 | K34: =-K33/K4 -> 0.036273636 | L34: =-L33/L4 -> 0.032515757 | ... N34: =-N33/N4 -> 0.025
B36: CapEx intangibles | E36: ='3-Statement Model'!J173 -> -25.04757 | F36: ='3-Statement Model'!K173 -> -26.367489 | G36: ='3-Statement Model'!L173 -> -28.127059 | H36: ='3-Statement Model'!M173 -> -29.842379 | I36: ='3-Statement Model'!N173 -> -31.487403 | J36: ='3-Statement Model'!O173 -> -33.052873 | K36: ='3-Statement Model'!P173 -> -34.517361 | L36: ='3-Statement Model'!Q173 -> -35.859902 | ... N36: ='3-Statement Model'!S173 -> -38.100512
B37: % of revenue | E37: =-E36/E4 -> 0.00221362 | F37: =-F36/F4 -> 0.00221362 | G37: =-G36/G4 -> 0.00221362 | H37: =-H36/H4 -> 0.00221362 | I37: =-I36/I4 -> 0.00221362 | J37: =-J36/J4 -> 0.00221362 | K37: =-K36/K4 -> 0.00221362 | L37: =-L36/L4 -> 0.00221362 | ... N37: =-N36/N4 -> 0.00221362
B39: M&A investments | E39: ='3-Statement Model'!J174 -> -253.7802 | F39: ='3-Statement Model'!K174 -> -317.03763 | G39: ='3-Statement Model'!L174 -> -333.7444 | H39: ='3-Statement Model'!M174 -> -356.01602 | I39: ='3-Statement Model'!N174 -> -377.72755 | J39: ='3-Statement Model'!O174 -> -341.38546 | K39: ='3-Statement Model'!P174 -> -298.63187 | L39: ='3-Statement Model'!Q174 -> -218.30443 | ... N39: ='3-Statement Model'!S174 -> 0
B40: % of revenue | E40: =-E39/E4 -> 0.02242824 | F40: =-F39/F4 -> 0.026616142 | G40: =-G39/G4 -> 0.026265927 | H40: =-H39/H4 -> 0.026408222 | I40: =-I39/I4 -> 0.026554913 | J40: =-J39/J4 -> 0.022863298 | K40: =-K39/K4 -> 0.019151448 | L40: =-L39/L4 -> 0.013475861 | ... N40: =-N39/N4 -> 0
B42: FCFF | E42: =E20+SUM(E23:E31)+E33+E36+E39 -> 997.86171 | F42: =F20+SUM(F23:F31)+F33+F36+F39 -> 1214.9975 | G42: =G20+SUM(G23:G31)+G33+G36+G39 -> 1395.1052 | H42: =H20+SUM(H23:H31)+H33+H36+H39 -> 1341.5631 | I42: =I20+SUM(I23:I31)+I33+I36+I39 -> 1453.0394 | J42: =J20+SUM(J23:J31)+J33+J36+J39 -> 1601.5651 | K42: =K20+SUM(K23:K31)+K33+K36+K39 -> 1799.0485 | L42: =L20+SUM(L23:L31)+L33+L36+L39 -> 2032.7156 | ... N42: =N20+SUM(N23:N31)+N33+N36+N39 -> 2480.6134
B45: Last fiscal year end | D45: 45657
B46: End of the first fiscal year | D46: 46022
B47: Valuation date | D47: 45961
B48: Fraction of first year cash flows forecast => Stub period | D48: =YEARFRAC(D47,D46) -> 0.16666667
B49: FCF in the last year of explicit forecast 2034 | D49: =N59 -> 2480.6134
B50: EBITDA in last year of explicit forecast 2034 | D50: =N14+N23 -> 3666.1257
B51: WACC | D51: =WACC!D23 -> 0.080719126
B53: Fiscal year ended | D53: 45657 | E53: 46022 | F53: 46387 | G53: 46752 | H53: 47118 | I53: 47483 | J53: 47848 | K53: 48213 | L53: 48579 | M53: 48944 | N53: 49309
B55: FCFF | E55: =E42 -> 997.86171 | F55: =F42 -> 1214.9975 | G55: =G42 -> 1395.1052 | H55: =H42 -> 1341.5631 | I55: =I42 -> 1453.0394 | J55: =J42 -> 1601.5651 | K55: =K42 -> 1799.0485 | L55: =L42 -> 2032.7156 | ... N55: =N42 -> 2480.6134
D57: Val date | E57: 1 | F57: =E57+1 -> 2 | G57: =F57+1 -> 3 | H57: =G57+1 -> 4 | I57: =H57+1 -> 5 | J57: =I57+1 -> 6 | K57: =J57+1 -> 7 | L57: =K57+1 -> 8 | M57: =L57+1 -> 9 | N57: =M57+1 -> 10
B58: Date for disocunting cash flows - mid of the year | D58: 45982 | E58: =AVERAGE(D58,E53) -> 46002 | F58: =AVERAGE(E53,F53) -> 46204.5 | G58: =AVERAGE(F53,G53) -> 46569.5 | H58: =AVERAGE(G53,H53) -> 46935 | I58: =AVERAGE(H53,I53) -> 47300.5 | J58: =AVERAGE(I53,J53) -> 47665.5 | K58: =AVERAGE(J53,K53) -> 48030.5 | L58: =AVERAGE(K53,L53) -> 48396 | M58: =AVERAGE(L53,M53) -> 48761.5 | N58: =AVERAGE(M53,N53) -> 49126.5
...

Sheet Assumptions
C2: Working Case | E2: Management
B5: x | C5: Assumptions | E5: 2020 | F5: =E5+1 -> 2021 | G5: =F5+1 -> 2022 | H5: =G5+1 -> 2023 | I5: =H5+1 -> 2024 | J5: =I5+1 -> 2025 | K5: =J5+1 -> 2026 | L5: =K5+1 -> 2027 | M5: =L5+1 -> 2028 | ... S5: =R5+1 -> 2034
B7: x | C7: Working Case | E7: 2020 | F7: 2021 | G7: 2022 | H7: 2023 | I7: 2024 | J7: 2025 | K7: 2026 | L7: 2027 | M7: 2028 | N7: 2029 | O7: 2029 | P7: 2029 | Q7: 2029 | R7: 2029 | S7: 2029
B9: x | C9: Revenue
C10: EMEA (% growth) | E10: =CHOOSE(MATCH($E$2,{"Management";"Conservative"},0),E119,#REF!) -> -- | F10: =CHOOSE(MATCH($E$2,{"Management";"Conservative"},0),F119,#REF!) -> 0.16478801 | G10: =CHOOSE(MATCH($E$2,{"Management";"Conservative"},0),G119,#REF!) -> 0.017708896 | H10: =CHOOSE(MATCH($E$2,{"Management";"Conservative"},0),H119,#REF!) -> 0.17767588 | I10: =CHOOSE(MATCH($E$2,{"Management";"Conservative"},0),I119,#REF!) -> 0.044162551 | J10: =CHOOSE(MATCH($E$2,{"Management";"Conservative"},0),J119,#REF!) -> -0.01204749 | K10: =CHOOSE(MATCH($E$2,{"Management";"Conservative"},0),K119,#REF!) -> 0.052486486 | L10: =CHOOSE(MATCH($E$2,{"Management";"Conservative"},0),L119,#REF!) -> 0.056324324 | ... S10: =CHOOSE(MATCH($E$2,{"Management";"Conservative"},0),S119,#REF!) -> 0.028
C11: Americas (% growth) | E11: =CHOOSE(MATCH($E$2,{"Management";"Conservative"},0),E120,#REF!) -> -- | F11: =CHOOSE(MATCH($E$2,{"Management";"Conservative"},0),F120,#REF!) -> 0.20634132 | G11: =CHOOSE(MATCH($E$2,{"Management";"Conservative"},0),G120,#REF!) -> 0.31560517 | H11: =CHOOSE(MATCH($E$2,{"Management";"Conservative"},0),H120,#REF!) -> 0.169845 | I11: =CHOOSE(MATCH($E$2,{"Management";"Conservative"},0),I120,#REF!) -> 0.096629995 | J11: =CHOOSE(MATCH($E$2,{"Management";"Conservative"},0),J120,#REF!) -> -0.041 | K11: =CHOOSE(MATCH($E$2,{"Management";"Conservative"},0),K120,#REF!) -> 0.045 | L11: =CHOOSE(MATCH($E$2,{"Management";"Conservative"},0),L120,#REF!) -> 0.08 | ... S11: =CHOOSE(MATCH($E$2,{"Management";"Conservative"},0),S120,#REF!) -> 0.0287
C12: Asia/Pacific (% growth) | E12: =CHOOSE(MATCH($E$2,{"Management";"Conservative"},0),E121,#REF!) -> -- | F12: =CHOOSE(MATCH($E$2,{"Management";"Conservative"},0),F121,#REF!) -> 0.20750885 | G12: =CHOOSE(MATCH($E$2,{"Management";"Conservative"},0),G121,#REF!) -> 0.12960738 | H12: =CHOOSE(MATCH($E$2,{"Management";"Conservative"},0),H121,#REF!) -> 0.11588531 | I12: =CHOOSE(MATCH($E$2,{"Management";"Conservative"},0),I121,#REF!) -> -0.019824628 | J12: =CHOOSE(MATCH($E$2,{"Management";"Conservative"},0),J121,#REF!) -> -0.085 | K12: =CHOOSE(MATCH($E$2,{"Management";"Conservative"},0),K121,#REF!) -> 0.066 | L12: =CHOOSE(MATCH($E$2,{"Management";"Conservative"},0),L121,#REF!) -> 0.067 | ... S12: =CHOOSE(MATCH($E$2,{"Management";"Conservative"},0),S121,#REF!) -> 0.0271
C13: Global Business (% growth) | E13: =CHOOSE(MATCH($E$2,{"Management";"Conservative"},0),E122,#REF!) -> -- | F13: =CHOOSE(MATCH($E$2,{"Management";"Conservative"},0),F122,#REF!) -> 0.040049482 | G13: =CHOOSE(MATCH($E$2,{"Management";"Conservative"},0),G122,#REF!) -> 0.19565864 | H13: =CHOOSE(MATCH($E$2,{"Management";"Conservative"},0),H122,#REF!) -> -1 | I13: =CHOOSE(MATCH($E$2,{"Management";"Conservative"},0),I122,#REF!) -> #DIV/0! | J13: =CHOOSE(MATCH($E$2,{"Management";"Conservative"},0),J122,#REF!) -> 0 | K13: =CHOOSE(MATCH($E$2,{"Management";"Conservative"},0),K122,#REF!) -> 0 | L13: =CHOOSE(MATCH($E$2,{"Management";"Conservative"},0),L122,#REF!) -> 0 | ... S13: =CHOOSE(MATCH($E$2,{"Management";"Conservative"},0),S122,#REF!) -> 0
B15: x | C15: COGS
C16: Cost of Goods Sold (% of revenue) | E16: =CHOOSE(MATCH($E$2,{"Management";"Conservative"},0),E125,#REF!) -> 0.45225703 | F16: =CHOOSE(MATCH($E$2,{"Management";"Conservative"},0),F125,#REF!) -> 0.48215038 | G16: =CHOOSE(MATCH($E$2,{"Management";"Conservative"},0),G125,#REF!) -> 0.50630016 | H16: =CHOOSE(MATCH($E$2,{"Management";"Conservative"},0),H125,#REF!) -> 0.46391899 | I16: =CHOOSE(MATCH($E$2,{"Management";"Conservative"},0),I125,#REF!) -> 0.45456555 | J16: =CHOOSE(MATCH($E$2,{"Management";"Conservative"},0),J125,#REF!) -> 0.45 | K16: =CHOOSE(MATCH($E$2,{"Management";"Conservative"},0),K125,#REF!) -> 0.45 | L16: =CHOOSE(MATCH($E$2,{"Management";"Conservative"},0),L125,#REF!) -> 0.45 | ... S16: =CHOOSE(MATCH($E$2,{"Management";"Conservative"},0),S125,#REF!) -> 0.45
B18: x | C18: OpEx
C19: Personnel Expenses (% of revenue) | E19: =CHOOSE(MATCH($E$2,{"Management";"Conservative"},0),E128,#REF!) -> 0.19370113 | F19: =CHOOSE(MATCH($E$2,{"Management";"Conservative"},0),F128,#REF!) -> 0.17674524 | G19: =CHOOSE(MATCH($E$2,{"Management";"Conservative"},0),G128,#REF!) -> 0.16303208 | H19: =CHOOSE(MATCH($E$2,{"Management";"Conservative"},0),H128,#REF!) -> 0.17856317 | I19: =CHOOSE(MATCH($E$2,{"Management";"Conservative"},0),I128,#REF!) -> 0.18223087 | J19: =CHOOSE(MATCH($E$2,{"Management";"Conservative"},0),J128,#REF!) -> 0.189 | K19: =CHOOSE(MATCH($E$2,{"Management";"Conservative"},0),K128,#REF!) -> 0.182 | L19: =CHOOSE(MATCH($E$2,{"Management";"Conservative"},0),L128,#REF!) -> 0.177 | ... S19: =CHOOSE(MATCH($E$2,{"Management";"Conservative"},0),S128,#REF!) -> 0.177
C20: Production and Operations (% of revenue) | E20: =CHOOSE(MATCH($E$2,{"Management";"Conservative"},0),E129,#REF!) -> 0.050713415 | F20: =CHOOSE(MATCH($E$2,{"Management";"Conservative"},0),F129,#REF!) -> 0.050419896 | G20: =CHOOSE(MATCH($E$2,{"Management";"Conservative"},0),G129,#REF!) -> 0.047513296 | H20: =CHOOSE(MATCH($E$2,{"Management";"Conservative"},0),H129,#REF!) -> 0.051029488 | I20: =CHOOSE(MATCH($E$2,{"Management";"Conservative"},0),I129,#REF!) -> 0.052843213 | J20: =CHOOSE(MATCH($E$2,{"Management";"Conservative"},0),J129,#REF!) -> 0.052 | K20: =CHOOSE(MATCH($E$2,{"Management";"Conservative"},0),K129,#REF!) -> 0.051 | L20: =CHOOSE(MATCH($E$2,{"Management";"Conservative"},0),L129,#REF!) -> 0.05 | ... S20: =CHOOSE(MATCH($E$2,{"Management";"Conservative"},0),S129,#REF!) -> 0.049
C21: Logistics and Distribution (% of revenue) | E21: =CHOOSE(MATCH($E$2,{"Management";"Conservative"},0),E130,#REF!) -> 0.050979994 | F21: =CHOOSE(MATCH($E$2,{"Management";"Conservative"},0),F130,#REF!) -> 0.051554749 | G21: =CHOOSE(MATCH($E$2,{"Management";"Conservative"},0),G130,#REF!) -> 0.049505328 | H21: =CHOOSE(MATCH($E$2,{"Management";"Conservative"},0),H130,#REF!) -> 0.050371043 | I21: =CHOOSE(MATCH($E$2,{"Management";"Conservative"},0),I130,#REF!) -> 0.051457524 | J21: =CHOOSE(MATCH($E$2,{"Management";"Conservative"},0),J130,#REF!) -> 0.05 | K21: =CHOOSE(MATCH($E$2,{"Management";"Conservative"},0),K130,#REF!) -> 0.049 | L21: =CHOOSE(MATCH($E$2,{"Management";"Conservative"},0),L130,#REF!) -> 0.049 | ... S21: =CHOOSE(MATCH($E$2,{"Management";"Conservative"},0),S130,#REF!) -> 0.048
C22: Sales, Marketing and Travel Costs (% of revenue) | E22: =CHOOSE(MATCH($E$2,{"Management";"Conservative"},0),E131,#REF!) -> 0.02691175 | F22: =CHOOSE(MATCH($E$2,{"Management";"Conservative"},0),F131,#REF!) -> 0.025409898 | G22: =CHOOSE(MATCH($E$2,{"Management";"Conservative"},0),G131,#REF!) -> 0.028927353 | H22: =CHOOSE(MATCH($E$2,{"Management";"Conservative"},0),H131,#REF!) -> 0.03296674 | I22: =CHOOSE(MATCH($E$2,{"Management";"Conservative"},0),I131,#REF!) -> 0.031530804 | J22: =CHOOSE(MATCH($E$2,{"Management";"Conservative"},0),J131,#REF!) -> 0.031 | K22: =CHOOSE(MATCH($E$2,{"Management";"Conservative"},0),K131,#REF!) -> 0.03 | L22: =CHOOSE(MATCH($E$2,{"Management";"Conservative"},0),L131,#REF!) -> 0.029 | ... S22: =CHOOSE(MATCH($E$2,{"Management";"Conservative"},0),S131,#REF!) -> 0.029
C23: Administration Costs (% of revenue) | E23: =CHOOSE(MATCH($E$2,{"Management";"Conservative"},0),E132,#REF!) -> 0.035315324 | F23: =CHOOSE(MATCH($E$2,{"Management";"Conservative"},0),F132,#REF!) -> 0.025874647 | G23: =CHOOSE(MATCH($E$2,{"Management";"Conservative"},0),G132,#REF!) -> 0.017508912 | H23: =CHOOSE(MATCH($E$2,{"Management";"Conservative"},0),H132,#REF!) -> 0.041215098 | I23: =CHOOSE(MATCH($E$2,{"Management";"Conservative"},0),I132,#REF!) -> 0.034438201 | J23: =CHOOSE(MATCH($E$2,{"Management";"Conservative"},0),J132,#REF!) -> 0.036 | K23: =CHOOSE(MATCH($E$2,{"Management";"Conservative"},0),K132,#REF!) -> 0.035 | L23: =CHOOSE(MATCH($E$2,{"Management";"Conservative"},0),L132,#REF!) -> 0.035 | ... S23: =CHOOSE(MATCH($E$2,{"Management";"Conservative"},0),S132,#REF!) -> 0.034
C25: CapEx
C26: Own property, plant and equipment | E26: =CHOOSE(MATCH($E$2,{"Management";"Conservative"},0),E135,#REF!) -> 120.1 | F26: =CHOOSE(MATCH($E$2,{"Management";"Conservative"},0),F135,#REF!) -> 157.3 | G26: =CHOOSE(MATCH($E$2,{"Management";"Conservative"},0),G135,#REF!) -> 238 | H26: =CHOOSE(MATCH($E$2,{"Management";"Conservative"},0),H135,#REF!) -> 256.8 | I26: =CHOOSE(MATCH($E$2,{"Management";"Conservative"},0),I135,#REF!) -> 331.1 | J26: =CHOOSE(MATCH($E$2,{"Management";"Conservative"},0),J135,#REF!) -> 373.20623 | K26: =CHOOSE(MATCH($E$2,{"Management";"Conservative"},0),K135,#REF!) -> 391.09438 | L26: =CHOOSE(MATCH($E$2,{"Management";"Conservative"},0),L135,#REF!) -> 414.94089 | ... S26: =CHOOSE(MATCH($E$2,{"Management";"Conservative"},0),S135,#REF!) -> 292.60158
C27: % of revenue | E27: =CHOOSE(MATCH($E$2,{"Management";"Conservative"},0),E136,#REF!) -> 0.01524576 | F27: =CHOOSE(MATCH($E$2,{"Management";"Conservative"},0),F136,#REF!) -> 0.017001178 | G27: =CHOOSE(MATCH($E$2,{"Management";"Conservative"},0),G136,#REF!) -> 0.022684382 | H27: =CHOOSE(MATCH($E$2,{"Management";"Conservative"},0),H136,#REF!) -> 0.022849821 | I27: =CHOOSE(MATCH($E$2,{"Management";"Conservative"},0),I136,#REF!) -> 0.028147342 | J27: =CHOOSE(MATCH($E$2,{"Management";"Conservative"},0),J136,#REF!) -> 0.03 | K27: =CHOOSE(MATCH($E$2,{"Management";"Conservative"},0),K136,#REF!) -> 0.03 | L27: =CHOOSE(MATCH($E$2,{"Management";"Conservative"},0),L136,#REF!) -> 0.03 | ... S27: =CHOOSE(MATCH($E$2,{"Management";"Conservative"},0),S136,#REF!) -> 0.017
C28: Right-of-use assets | E28: =CHOOSE(MATCH($E$2,{"Management";"Conservative"},0),E137,#REF!) -> 72.4 | F28: =CHOOSE(MATCH($E$2,{"Management";"Conservative"},0),F137,#REF!) -> 75.7 | G28: =CHOOSE(MATCH($E$2,{"Management";"Conservative"},0),G137,#REF!) -> 104.5 | H28: =CHOOSE(MATCH($E$2,{"Management";"Conservative"},0),H137,#REF!) -> 120 | I28: =CHOOSE(MATCH($E$2,{"Management";"Conservative"},0),I137,#REF!) -> 134.3 | J28: =CHOOSE(MATCH($E$2,{"Management";"Conservative"},0),J137,#REF!) -> 125.00218 | K28: =CHOOSE(MATCH($E$2,{"Management";"Conservative"},0),K137,#REF!) -> 131.58936 | L28: =CHOOSE(MATCH($E$2,{"Management";"Conservative"},0),L137,#REF!) -> 140.37065 | ... S28: =CHOOSE(MATCH($E$2,{"Management";"Conservative"},0),S137,#REF!) -> 137.69486
C29: % of revenu | E29: =CHOOSE(MATCH($E$2,{"Management";"Conservative"},0),E138,#REF!) -> 0.0091906164 | F29: =CHOOSE(MATCH($E$2,{"Management";"Conservative"},0),F138,#REF!) -> 0.0081817494 | G29: =CHOOSE(MATCH($E$2,{"Management";"Conservative"},0),G138,#REF!) -> 0.0099601594 | H29: =CHOOSE(MATCH($E$2,{"Management";"Conservative"},0),H138,#REF!) -> 0.010677487 | I29: =CHOOSE(MATCH($E$2,{"Management";"Conservative"},0),I138,#REF!) -> 0.011417058 | J29: =CHOOSE(MATCH($E$2,{"Management";"Conservative"},0),J138,#REF!) -> 0.011047272 | K29: =CHOOSE(MATCH($E$2,{"Management";"Conservative"},0),K138,#REF!) -> 0.011047272 | L29: =CHOOSE(MATCH($E$2,{"Management";"Conservative"},0),L138,#REF!) -> 0.011047272 | ... S29: =CHOOSE(MATCH($E$2,{"Management";"Conservative"},0),S138,#REF!) -> 0.008
C30: Intangible assets | E30: =CHOOSE(MATCH($E$2,{"Management";"Conservative"},0),E139,#REF!) -> 11.6 | F30: =CHOOSE(MATCH($E$2,{"Management";"Conservative"},0),F139,#REF!) -> 13.5 | G30: =CHOOSE(MATCH($E$2,{"Management";"Conservative"},0),G139,#REF!) -> 28 | H30: =CHOOSE(MATCH($E$2,{"Management";"Conservative"},0),H139,#REF!) -> 23.1 | I30: =CHOOSE(MATCH($E$2,{"Management";"Conservative"},0),I139,#REF!) -> 27.9 | J30: =CHOOSE(MATCH($E$2,{"Management";"Conservative"},0),J139,#REF!) -> 25.04757 | K30: =CHOOSE(MATCH($E$2,{"Management";"Conservative"},0),K139,#REF!) -> 26.367489 | L30: =CHOOSE(MATCH($E$2,{"Management";"Conservative"},0),L139,#REF!) -> 28.127059 | ... S30: =CHOOSE(MATCH($E$2,{"Management";"Conservative"},0),S139,#REF!) -> 38.100512
C31: % of revenue | E31: =CHOOSE(MATCH($E$2,{"Management";"Conservative"},0),E140,#REF!) -> 0.0014725297 | F31: =CHOOSE(MATCH($E$2,{"Management";"Conservative"},0),F140,#REF!) -> 0.0014590967 | G31: =CHOOSE(MATCH($E$2,{"Management";"Conservative"},0),G140,#REF!) -> 0.0026687508 | H31: =CHOOSE(MATCH($E$2,{"Management";"Conservative"},0),H140,#REF!) -> 0.0020554162 | I31: =CHOOSE(MATCH($E$2,{"Management";"Conservative"},0),I140,#REF!) -> 0.0023718238 | J31: =CHOOSE(MATCH($E$2,{"Management";"Conservative"},0),J140,#REF!) -> 0.00221362 | K31: =CHOOSE(MATCH($E$2,{"Management";"Conservative"},0),K140,#REF!) -> 0.00221362 | L31: =CHOOSE(MATCH($E$2,{"Management";"Conservative"},0),L140,#REF!) -> 0.00221362 | ... S31: =CHOOSE(MATCH($E$2,{"Management";"Conservative"},0),S140,#REF!) -> 0.00221362
C33: M&A Investments
C34: % revenue growth trough M&A | J34: =CHOOSE(MATCH($E$2,{"Management";"Conservative"},0),J143,#REF!) -> 0.010787131 | K34: =CHOOSE(MATCH($E$2,{"Management";"Conservative"},0),K143,#REF!) -> 0.01400936 | L34: =CHOOSE(MATCH($E$2,{"Management";"Conservative"},0),L143,#REF!) -> 0.01400936 | M34: =CHOOSE(MATCH($E$2,{"Management";"Conservative"},0),M143,#REF!) -> 0.01400936 | N34: =CHOOSE(MATCH($E$2,{"Management";"Conservative"},0),N143,#REF!) -> 0.01400936 | O34: =CHOOSE(MATCH($E$2,{"Management";"Conservative"},0),O143,#REF!) -> 0.012 | P34: =CHOOSE(MATCH($E$2,{"Management";"Conservative"},0),P143,#REF!) -> 0.01 | Q34: =CHOOSE(MATCH($E$2,{"Management";"Conservative"},0),Q143,#REF!) -> 0.007 | ... S34: =CHOOSE(MATCH($E$2,{"Management";"Conservative"},0),S143,#REF!) -> 0
C35: Revenue growth through M&A | J35: =CHOOSE(MATCH($E$2,{"Management";"Conservative"},0),J144,#REF!) -> 126.8901 | K35: =CHOOSE(MATCH($E$2,{"Management";"Conservative"},0),K144,#REF!) -> 158.51882 | L35: =CHOOSE(MATCH($E$2,{"Management";"Conservative"},0),L144,#REF!) -> 166.8722 | M35: =CHOOSE(MATCH($E$2,{"Management";"Conservative"},0),M144,#REF!) -> 178.00801 | N35: =CHOOSE(MATCH($E$2,{"Management";"Conservative"},0),N144,#REF!) -> 188.86378 | O35: =CHOOSE(MATCH($E$2,{"Management";"Conservative"},0),O144,#REF!) -> 170.69273 | P35: =CHOOSE(MATCH($E$2,{"Management";"Conservative"},0),P144,#REF!) -> 149.31593 | Q35: =CHOOSE(MATCH($E$2,{"Management";"Conservative"},0),Q144,#REF!) -> 109.15222 | ... S35: =CHOOSE(MATCH($E$2,{"Management";"Conservative"},0),S144,#REF!) -> 0
C36: Average EV/Revenue multiple M&A | J36: =CHOOSE(MATCH($E$2,{"Management";"Conservative"},0),J145,#REF!) -> 2 | K36: =CHOOSE(MATCH($E$2,{"Management";"Conservative"},0),K145,#REF!) -> 2 | L36: =CHOOSE(MATCH($E$2,{"Management";"Conservative"},0),L145,#REF!) -> 2 | M36: =CHOOSE(MATCH($E$2,{"Management";"Conservative"},0),M145,#REF!) -> 2 | N36: =CHOOSE(MATCH($E$2,{"Management";"Conservative"},0),N145,#REF!) -> 2 | O36: =CHOOSE(MATCH($E$2,{"Management";"Conservative"},0),O145,#REF!) -> 2 | P36: =CHOOSE(MATCH($E$2,{"Management";"Conservative"},0),P145,#REF!) -> 2 | Q36: =CHOOSE(MATCH($E$2,{"Management";"Conservative"},0),Q145,#REF!) -> 2 | ... S36: =CHOOSE(MATCH($E$2,{"Management";"Conservative"},0),S145,#REF!) -> 2
C37: M&A Investments | J37: =CHOOSE(MATCH($E$2,{"Management";"Conservative"},0),J146,#REF!) -> 253.7802 | K37: =CHOOSE(MATCH($E$2,{"Management";"Conservative"},0),K146,#REF!) -> 317.03763 | L37: =CHOOSE(MATCH($E$2,{"Management";"Conservative"},0),L146,#REF!) -> 333.7444 | M37: =CHOOSE(MATCH($E$2,{"Management";"Conservative"},0),M146,#REF!) -> 356.01602 | N37: =CHOOSE(MATCH($E$2,{"Management";"Conservative"},0),N146,#REF!) -> 377.72755 | O37: =CHOOSE(MATCH($E$2,{"Management";"Conservative"},0),O146,#REF!) -> 341.38546 | P37: =CHOOSE(MATCH($E$2,{"Management";"Conservative"},0),P146,#REF!) -> 298.63187 | Q37: =CHOOSE(MATCH($E$2,{"Management";"Conservative"},0),Q146,#REF!) -> 218.30443 | ... S37: =CHOOSE(MATCH($E$2,{"Management";"Conservative"},0),S146,#REF!) -> 0
B39: x | C39: Interest
C40: Interest Income | E40: =CHOOSE(MATCH($E$2,{"Management";"Conservative"},0),E149,#REF!) -> 5.5 | F40: =CHOOSE(MATCH($E$2,{"Management";"Conservative"},0),F149,#REF!) -> 11.5 | G40: =CHOOSE(MATCH($E$2,{"Management";"Conservative"},0),G149,#REF!) -> 19 | H40: =CHOOSE(MATCH($E$2,{"Management";"Conservative"},0),H149,#REF!) -> 30.9 | I40: =CHOOSE(MATCH($E$2,{"Management";"Conservative"},0),I149,#REF!) -> 26.6 | J40: =CHOOSE(MATCH($E$2,{"Management";"Conservative"},0),J149,#REF!) -> 14.626968 | K40: =CHOOSE(MATCH($E$2,{"Management";"Conservative"},0),K149,#REF!) -> 20.415726 | L40: =CHOOSE(MATCH($E$2,{"Management";"Conservative"},0),L149,#REF!) -> 27.410596 | ... S40: =CHOOSE(MATCH($E$2,{"Management";"Conservative"},0),S149,#REF!) -> 97.553834
C41: Implied Interest rate % | F41: =CHOOSE(MATCH($E$2,{"Management";"Conservative"},0),F150,#REF!) -> 0.0087207098 | G41: =CHOOSE(MATCH($E$2,{"Management";"Conservative"},0),G150,#REF!) -> 0.016170213 | H41: =CHOOSE(MATCH($E$2,{"Management";"Conservative"},0),H150,#REF!) -> 0.016494955 | I41: =CHOOSE(MATCH($E$2,{"Management";"Conservative"},0),I150,#REF!) -> 0.041310763 | J41: =CHOOSE(MATCH($E$2,{"Management";"Conservative"},0),J150,#REF!) -> 0.02067416 | K41: =CHOOSE(MATCH($E$2,{"Management";"Conservative"},0),K150,#REF!) -> 0.02067416 | L41: =CHOOSE(MATCH($E$2,{"Management";"Conservative"},0),L150,#REF!) -> 0.02067416 | M41: =CHOOSE(MATCH($E$2,{"Management";"Conservative"},0),M150,#REF!) -> 0.02067416 | ... S41: =CHOOSE(MATCH($E$2,{"Management";"Conservative"},0),S150,#REF!) -> 0.02067416
C43: Other Financial Income | E43: =CHOOSE(MATCH($E$2,{"Management";"Conservative"},0),E152,#REF!) -> 6 | F43: =CHOOSE(MATCH($E$2,{"Management";"Conservative"},0),F152,#REF!) -> 7 | G43: =CHOOSE(MATCH($E$2,{"Management";"Conservative"},0),G152,#REF!) -> 6.9 | H43: =CHOOSE(MATCH($E$2,{"Management";"Conservative"},0),H152,#REF!) -> 7.3 | I43: =CHOOSE(MATCH($E$2,{"Management";"Conservative"},0),I152,#REF!) -> 7.3 | J43: =CHOOSE(MATCH($E$2,{"Management";"Conservative"},0),J152,#REF!) -> 6.9 | K43: =CHOOSE(MATCH($E$2,{"Management";"Conservative"},0),K152,#REF!) -> 6.9 | L43: =CHOOSE(MATCH($E$2,{"Management";"Conservative"},0),L152,#REF!) -> 6.9 | ... S43: =CHOOSE(MATCH($E$2,{"Management";"Conservative"},0),S152,#REF!) -> 6.9
C44: Other Financial Expenses | E44: =CHOOSE(MATCH($E$2,{"Management";"Conservative"},0),E153,#REF!) -> 24.7 | F44: =CHOOSE(MATCH($E$2,{"Management";"Conservative"},0),F153,#REF!) -> 17.8 | G44: =CHOOSE(MATCH($E$2,{"Management";"Conservative"},0),G153,#REF!) -> 48.4 | H44: =CHOOSE(MATCH($E$2,{"Management";"Conservative"},0),H153,#REF!) -> 86.3 | I44: =CHOOSE(MATCH($E$2,{"Management";"Conservative"},0),I153,#REF!) -> 2.5 | J44: =CHOOSE(MATCH($E$2,{"Management";"Conservative"},0),J153,#REF!) -> 23.35 | K44: =CHOOSE(MATCH($E$2,{"Management";"Conservative"},0),K153,#REF!) -> 23.35 | L44: =CHOOSE(MATCH($E$2,{"Management";"Conservative"},0),L153,#REF!) -> 23.35 | ... S44: =CHOOSE(MATCH($E$2,{"Management";"Conservative"},0),S153,#REF!) -> 23.35
C46: Income from Associated Companies | E46: =CHOOSE(MATCH($E$2,{"Management";"Conservative"},0),E155,#REF!) -> 0.5 | F46: =CHOOSE(MATCH($E$2,{"Management";"Conservative"},0),F155,#REF!) -> 0.4 | G46: =CHOOSE(MATCH($E$2,{"Management";"Conservative"},0),G155,#REF!) -> 0.4 | H46: =CHOOSE(MATCH($E$2,{"Management";"Conservative"},0),H155,#REF!) -> 1.1 | I46: =CHOOSE(MATCH($E$2,{"Management";"Conservative"},0),I155,#REF!) -> 3.6 | J46: =CHOOSE(MATCH($E$2,{"Management";"Conservative"},0),J155,#REF!) -> 3.6 | K46: =CHOOSE(MATCH($E$2,{"Management";"Conservative"},0),K155,#REF!) -> 3.6 | L46: =CHOOSE(MATCH($E$2,{"Management";"Conservative"},0),L155,#REF!) -> 3.6 | ... S46: =CHOOSE(MATCH($E$2,{"Management";"Conservative"},0),S155,#REF!) -> 3.6
C47: % of investments in associated companies | E47: =CHOOSE(MATCH($E$2,{"Management";"Conservative"},0),E156,#REF!) -> 0.2 | F47: =CHOOSE(MATCH($E$2,{"Management";"Conservative"},0),F156,#REF!) -> 0.043478261 | G47: =CHOOSE(MATCH($E$2,{"Management";"Conservative"},0),G156,#REF!) -> 0.042105263 | H47: =CHOOSE(MATCH($E$2,{"Management";"Conservative"},0),H156,#REF!) -> 0.057591623 | I47: =CHOOSE(MATCH($E$2,{"Management";"Conservative"},0),I156,#REF!) -> 0.14937759 | J47: =CHOOSE(MATCH($E$2,{"Management";"Conservative"},0),J156,#REF!) -> 0.14937759 | K47: =CHOOSE(MATCH($E$2,{"Management";"Conservative"},0),K156,#REF!) -> 0.14937759 | L47: =CHOOSE(MATCH($E$2,{"Management";"Conservative"},0),L156,#REF!) -> 0.14937759 | ... S47: =CHOOSE(MATCH($E$2,{"Management";"Conservative"},0),S156,#REF!) -> 0.14937759
B49: x | C49: Taxes
C50: Tax rate (% of EBT) | E50: =CHOOSE(MATCH($E$2,{"Management";"Conservative"},0),E159,#REF!) -> 0.22187647 | F50: =CHOOSE(MATCH($E$2,{"Management";"Conservative"},0),F159,#REF!) -> 0.21822742 | G50: =CHOOSE(MATCH($E$2,{"Management";"Conservative"},0),G159,#REF!) -> 0.22406888 | H50: =CHOOSE(MATCH($E$2,{"Management";"Conservative"},0),H159,#REF!) -> 0.20487878 | I50: =CHOOSE(MATCH($E$2,{"Management";"Conservative"},0),I159,#REF!) -> 0.20179143 | J50: =CHOOSE(MATCH($E$2,{"Management";"Conservative"},0),J159,#REF!) -> 0.20179143 | K50: =CHOOSE(MATCH($E$2,{"Management";"Conservative"},0),K159,#REF!) -> 0.20179143 | L50: =CHOOSE(MATCH($E$2,{"Management";"Conservative"},0),L159,#REF!) -> 0.20179143 | ... S50: =CHOOSE(MATCH($E$2,{"Management";"Conservative"},0),S159,#REF!) -> 0.20179143
B52: x | C52: Impairment (% or revenue)
C53: Impairment (% or revenue) | E53: =CHOOSE(MATCH($E$2,{"Management";"Conservative"},0),E162,#REF!) -> 0 | F53: =CHOOSE(MATCH($E$2,{"Management";"Conservative"},0),F162,#REF!) -> 0 | G53: =CHOOSE(MATCH($E$2,{"Management";"Conservative"},0),G162,#REF!) -> 0 | H53: =CHOOSE(MATCH($E$2,{"Management";"Conservative"},0),H162,#REF!) -> 0.00091648426 | I53: =CHOOSE(MATCH($E$2,{"Management";"Conservative"},0),I162,#REF!) -> 0 | J53: =CHOOSE(MATCH($E$2,{"Management";"Conservative"},0),J162,#REF!) -> 0 | K53: =CHOOSE(MATCH($E$2,{"Management";"Conservative"},0),K162,#REF!) -> 0 | L53: =CHOOSE(MATCH($E$2,{"Management";"Conservative"},0),L162,#REF!) -> 0 | ... S53: =CHOOSE(MATCH($E$2,{"Management";"Conservative"},0),S162,#REF!) -> 0
C55: Net Income
...

Sheet WACC
B3: CHF | C3: Low | D3: Mid | E3: High | F3: Comments
B4: Risk free rate | C4: =D4 -> 0.00204 | D4: =E4 -> 0.00204 | E4: 0.00204 | F4: 10/30y gov bond of ch
B5: Equity market risk premium | C5: 0.07 | D5: =AVERAGE(E5,C5) -> 0.075 | E5: 0.08 | F5: Damodaran adj for country exposure
B6: Asset Beta | C6: 0.95 | D6: =AVERAGE(E6,C6) -> 1.025 | E6: 1.1 | F6: Avg and median beta of peer companies
B7: Gearing | C7: =C22/C21 -> 1 | D7: =D22/D21 -> 0.81818182 | E7: =E22/E21 -> 0.66666667 | F7: D/E ratio
B8: Re-levered beta | C8: =C6*(1+(1-C18)*C7) -> 1.7081 | D8: =D6*(1+(1-D18)*D7) -> 1.6942318 | E8: =E6*(1+(1-E18)*E7) -> 1.6852 | F8: TBD if Harris pringle or Hamada
B9: Cost of Equity | C9: =C4+C5*C8 -> 0.121607 | D9: =D4+D5*D8 -> 0.12910739 | E9: =E4+E5*E8 -> 0.136856
B11: Country risk premium | C11: 0 | D11: 0 | E11: 0
B12: Adjusted Cost of Equity | C12: =C9+C11 -> 0.121607 | D12: =D9+D11 -> 0.12910739 | E12: =E9+E11 -> 0.136856
B14: Risk free rate | C14: =C4 -> 0.00204 | D14: =D4 -> 0.00204 | E14: =E4 -> 0.00204 | F14: =F4 -> 10/30y gov bond of ch
B15: Credit spread | C15: 0.025 | D15: 0.025 | E15: 0.025 | F15: Credit spread for A- rated companies
B16: Pre-tax Cost of Debt | C16: =C14+C15 -> 0.02704 | D16: =D14+D15 -> 0.02704 | E16: =E14+E15 -> 0.02704
B18: Tax rate | C18: =D18 -> 0.202 | D18: =E18 -> 0.202 | E18: 0.202 | F18: Historical data
B19: After-tax Cost of Debt | C19: =C16*(1-C18) -> 0.02157792 | D19: =D16*(1-D18) -> 0.02157792 | E19: =E16*(1-E18) -> 0.02157792
B21: Equity-to-capital ratio | C21: 0.5 | D21: =AVERAGE(E21,C21) -> 0.55 | E21: 0.6 | F21: From peers
B22: Debt-to-capital ratio | C22: =1-C21 -> 0.5 | D22: =1-D21 -> 0.45 | E22: =1-E21 -> 0.4 | F22: From peers
B23: WACC | C23: =C12*C21+C19*C22 -> 0.07159246 | D23: =D12*D21+D19*D22 -> 0.080719126 | E23: =E12*E21+E19*E22 -> 0.090744768

Sheet Terminal Growth Rate
B3: Region | C3: Average Real GDP Growth | D3: 2034E Weight
B5: EMEA | C5: 0.013 | D5: 0.433 | E5: =C5+D9*D10 -> 0.028
B6: Americas | C6: 0.0137 | D6: 0.335 | E6: =C6+D9*D10 -> 0.0287
B7: APAC | C7: 0.0121 | D7: 0.232 | E7: =C7+D9*D10 -> 0.0271
B8: Weighted Average Real GDP Growth | D8: =C5*D5+C6*D6+C7*D7 -> 0.0130257
B9: LT inflation | D9: 0.02
B10: Inflation pass through | D10: 0.75
B11: Long Term Growth Rate | D11: =D8+D9*D10 -> 0.0280257
B13: Source: OECD

Sheet Asset Life
B3: Own property, plant and equipment | D3: 2020 | E3: =D3+1 -> 2021 | F3: =E3+1 -> 2022 | G3: =F3+1 -> 2023 | H3: =G3+1 -> 2024
B5: Acquisition cost | D5: 3267.4 | E5: 3442 | F5: 3549.1 | G5: 3973.3 | H5: 4394
B6: Depreciation expense | D6: 169.3 | E6: 165.8 | F6: 174.5 | G6: 200 | H6: 220.7
B7: Accumulated depreciation | D7: 1880.1 | E7: 1986.6 | F7: 2060.4 | G7: 2108 | H7: 2349.2
B8: Useful life | D8: =D5/D6 -> 19.299468 | E8: =E5/E6 -> 20.759952 | F8: =F5/F6 -> 20.338682 | G8: =G5/G6 -> 19.8665 | H8: =H5/H6 -> 19.909379
B9: Average age | D9: =D7/D6 -> 11.105139 | E9: =E7/E6 -> 11.981906 | F9: =F7/F6 -> 11.80745 | G9: =G7/G6 -> 10.54 | H9: =H7/H6 -> 10.644314
B11: Useful life | C11: =AVERAGE(D8:H8) -> 20.034796
B12: Average age | C12: =AVERAGE(D9:H9) -> 11.215762
B15: Right-of-use assets | D15: 2020 | E15: =D15+1 -> 2021 | F15: =E15+1 -> 2022 | G15: =F15+1 -> 2023 | H15: =G15+1 -> 2024
B17: Acquisition cost | D17: 446.4 | E17: 504.8 | F17: 552.6 | G17: 649.7 | H17: 751.5
B18: Depreciation expense | D18: 85.5 | E18: 84.5 | F18: 86.1 | G18: 106 | H18: 120.8
B19: Accumulated depreciation | D19: 131.1 | E19: 183.6 | F19: 219 | G19: 257.7 | H19: 337.8
B20: Useful life | D20: =D17/D18 -> 5.2210526 | E20: =E17/E18 -> 5.9739645 | F20: =F17/F18 -> 6.4181185 | G20: =G17/G18 -> 6.1292453 | H20: =H17/H18 -> 6.2210265
B21: Average life | D21: =D19/D18 -> 1.5333333 | E21: =E19/E18 -> 2.1727811 | F21: =F19/F18 -> 2.543554 | G21: =G19/G18 -> 2.4311321 | H21: =H19/H18 -> 2.7963576
B23: Useful life | C23: =AVERAGE(D20:H20) -> 5.9926815
B24: Average age | C24: =AVERAGE(D21:H21) -> 2.2954316
B27: Intangible assets | D27: 2020 | E27: =D27+1 -> 2021 | F27: =E27+1 -> 2022 | G27: =F27+1 -> 2023 | H27: =G27+1 -> 2024
B29: Acquisition cost | D29: 1644.2 | E29: 1752.5 | F29: 1774.5 | G29: 2886.2 | H29: 3123.1
B30: Amortization expense | D30: 112.3 | E30: 116.3 | F30: 123.9 | G30: 179.3 | H30: 214.1
B31: Accumulated amortization | D31: 560.7 | E31: 669.2 | F31: 771.1 | G31: 863 | H31: 1076.4
B32: Useful life | D32: =D29/D30 -> 14.64114 | E32: =E29/E30 -> 15.068788 | F32: =F29/F30 -> 14.322034 | G32: =G29/G30 -> 16.097044 | H32: =H29/H30 -> 14.587109
B33: Average life | D33: =D31/D30 -> 4.9928762 | E33: =E31/E30 -> 5.7540843 | F33: =F31/F30 -> 6.2235674 | G33: =G31/G30 -> 4.8131623 | H33: =H31/H30 -> 5.0275572
B35: Useful life | C35: =AVERAGE(D32:H32) -> 14.943223
B36: Average age | C36: =AVERAGE(D33:H33) -> 5.3622495

Sheet Tables
B3: Ratio Forecast
B5: Profitability | C5: =2023 -> 2023 | D5: =C5+1 -> 2024 | E5: =D5+1 -> 2025 | F5: =E5+1 -> 2026 | G5: =F5+1 -> 2027 | H5: =G5+1 -> 2028 | I5: =H5+1 -> 2029 | J5: =I5+1 -> 2030 | K5: =J5+1 -> 2031 | ... N5: =M5+1 -> 2034
B6: Gross Margin | C6: ='3-Statement Model'!H33 -> 0.53608101 | D6: ='3-Statement Model'!I33 -> 0.54543445 | E6: ='3-Statement Model'!J33 -> 0.55 | F6: ='3-Statement Model'!K33 -> 0.55 | G6: ='3-Statement Model'!L33 -> 0.55 | H6: ='3-Statement Model'!M33 -> 0.55 | I6: ='3-Statement Model'!N33 -> 0.55 | J6: ='3-Statement Model'!O33 -> 0.55 | ... N6: ='3-Statement Model'!S33 -> 0.55
B7: EBITDA Margin | C7: ='3-Statement Model'!H56 -> 0.18193547 | D7: ='3-Statement Model'!I56 -> 0.19293384 | E7: ='3-Statement Model'!J56 -> 0.192 | F7: ='3-Statement Model'!K56 -> 0.203 | G7: ='3-Statement Model'!L56 -> 0.21 | H7: ='3-Statement Model'!M56 -> 0.213 | I7: ='3-Statement Model'!N56 -> 0.213 | J7: ='3-Statement Model'!O56 -> 0.213 | ... N7: ='3-Statement Model'!S56 -> 0.213
B8: EBIT Margin | C8: ='3-Statement Model'!H73 -> 0.13783745 | D8: ='3-Statement Model'!I73 -> 0.14570139 | E8: ='3-Statement Model'!J73 -> 0.13910299 | F8: ='3-Statement Model'!K73 -> 0.14921281 | G8: ='3-Statement Model'!L73 -> 0.15615789 | H8: ='3-Statement Model'!M73 -> 0.16144776 | I8: ='3-Statement Model'!N73 -> 0.16651389 | J8: ='3-Statement Model'!O73 -> 0.1656833 | ... N8: ='3-Statement Model'!S73 -> 0.18591253
B9: EBT Margin | C9: ='3-Statement Model'!H93 -> 0.11891161 | D9: ='3-Statement Model'!I93 -> 0.13287314 | E9: ='3-Statement Model'!J93 -> 0.12629637 | F9: ='3-Statement Model'!K93 -> 0.1377022 | G9: ='3-Statement Model'!L93 -> 0.1461921 | H9: ='3-Statement Model'!M93 -> 0.15296063 | I9: ='3-Statement Model'!N93 -> 0.15900147 | J9: ='3-Statement Model'!O93 -> 0.15901454 | ... N9: ='3-Statement Model'!S93 -> 0.18291933
B10: Net Margin | C10: ='3-Statement Model'!H99 -> 0.094549143 | D10: ='3-Statement Model'!I99 -> 0.10606048 | E10: ='3-Statement Model'!J99 -> 0.10081084 | F10: ='3-Statement Model'!K99 -> 0.10991507 | G10: ='3-Statement Model'!L99 -> 0.11669179 | H10: ='3-Statement Model'!M99 -> 0.12209449 | I10: ='3-Statement Model'!N99 -> 0.12691634 | J10: ='3-Statement Model'!O99 -> 0.12692677 | ... N10: ='3-Statement Model'!S99 -> 0.14600778
B11: ROE | C11: ='3-Statement Model'!H98/(('3-Statement Model'!H148+'3-Statement Model'!G148)/2) -> 0.19496711 | D11: ='3-Statement Model'!I98/(('3-Statement Model'!I148+'3-Statement Model'!H148)/2) -> 0.19223421 | E11: ='3-Statement Model'!J98/(('3-Statement Model'!J148+'3-Statement Model'!I148)/2) -> 0.15512781 | F11: ='3-Statement Model'!K98/(('3-Statement Model'!K148+'3-Statement Model'!J148)/2) -> 0.16375509 | G11: ='3-Statement Model'!L98/(('3-Statement Model'!L148+'3-Statement Model'!K148)/2) -> 0.17058464 | H11: ='3-Statement Model'!M98/(('3-Statement Model'!M148+'3-Statement Model'!L148)/2) -> 0.17447208 | I11: ='3-Statement Model'!N98/(('3-Statement Model'!N148+'3-Statement Model'!M148)/2) -> 0.17682269 | J11: ='3-Statement Model'!O98/(('3-Statement Model'!O148+'3-Statement Model'!N148)/2) -> 0.17236225 | ... N11: ='3-Statement Model'!S98/(('3-Statement Model'!S148+'3-Statement Model'!R148)/2) -> 0.17878416
B12: ROA | C12: ='3-Statement Model'!H98/(('3-Statement Model'!H126+'3-Statement Model'!G126)/2) -> 0.079283716 | D12: ='3-Statement Model'!I98/(('3-Statement Model'!I126+'3-Statement Model'!H126)/2) -> 0.080417687 | E12: ='3-Statement Model'!J98/(('3-Statement Model'!J126+'3-Statement Model'!I126)/2) -> 0.070416872 | F12: ='3-Statement Model'!K98/(('3-Statement Model'!K126+'3-Statement Model'!J126)/2) -> 0.078241988 | G12: ='3-Statement Model'!L98/(('3-Statement Model'!L126+'3-Statement Model'!K126)/2) -> 0.085324867 | H12: ='3-Statement Model'!M98/(('3-Statement Model'!M126+'3-Statement Model'!L126)/2) -> 0.090684216 | I12: ='3-Statement Model'!N98/(('3-Statement Model'!N126+'3-Statement Model'!M126)/2) -> 0.0947897 | J12: ='3-Statement Model'!O98/(('3-Statement Model'!O126+'3-Statement Model'!N126)/2) -> 0.095022342 | ... N12: ='3-Statement Model'!S98/(('3-Statement Model'!S126+'3-Statement Model'!R126)/2) -> 0.10747825
